{
 "cells": [
  {
   "cell_type": "code",
   "execution_count": 1,
   "id": "41369c70-9514-4e62-9f97-306996872ff3",
   "metadata": {},
   "outputs": [
    {
     "name": "stderr",
     "output_type": "stream",
     "text": [
      "\n",
      "A module that was compiled using NumPy 1.x cannot be run in\n",
      "NumPy 2.2.0 as it may crash. To support both 1.x and 2.x\n",
      "versions of NumPy, modules must be compiled with NumPy 2.0.\n",
      "Some module may need to rebuild instead e.g. with 'pybind11>=2.12'.\n",
      "\n",
      "If you are a user of the module, the easiest solution will be to\n",
      "downgrade to 'numpy<2' or try to upgrade the affected module.\n",
      "We expect that some modules will need time to support NumPy 2.\n",
      "\n",
      "Traceback (most recent call last):  File \"<frozen runpy>\", line 198, in _run_module_as_main\n",
      "  File \"<frozen runpy>\", line 88, in _run_code\n",
      "  File \"C:\\Users\\pc\\anaconda3\\Lib\\site-packages\\ipykernel_launcher.py\", line 17, in <module>\n",
      "    app.launch_new_instance()\n",
      "  File \"C:\\Users\\pc\\anaconda3\\Lib\\site-packages\\traitlets\\config\\application.py\", line 1075, in launch_instance\n",
      "    app.start()\n",
      "  File \"C:\\Users\\pc\\anaconda3\\Lib\\site-packages\\ipykernel\\kernelapp.py\", line 701, in start\n",
      "    self.io_loop.start()\n",
      "  File \"C:\\Users\\pc\\anaconda3\\Lib\\site-packages\\tornado\\platform\\asyncio.py\", line 205, in start\n",
      "    self.asyncio_loop.run_forever()\n",
      "  File \"C:\\Users\\pc\\anaconda3\\Lib\\asyncio\\windows_events.py\", line 322, in run_forever\n",
      "    super().run_forever()\n",
      "  File \"C:\\Users\\pc\\anaconda3\\Lib\\asyncio\\base_events.py\", line 641, in run_forever\n",
      "    self._run_once()\n",
      "  File \"C:\\Users\\pc\\anaconda3\\Lib\\asyncio\\base_events.py\", line 1986, in _run_once\n",
      "    handle._run()\n",
      "  File \"C:\\Users\\pc\\anaconda3\\Lib\\asyncio\\events.py\", line 88, in _run\n",
      "    self._context.run(self._callback, *self._args)\n",
      "  File \"C:\\Users\\pc\\anaconda3\\Lib\\site-packages\\ipykernel\\kernelbase.py\", line 534, in dispatch_queue\n",
      "    await self.process_one()\n",
      "  File \"C:\\Users\\pc\\anaconda3\\Lib\\site-packages\\ipykernel\\kernelbase.py\", line 523, in process_one\n",
      "    await dispatch(*args)\n",
      "  File \"C:\\Users\\pc\\anaconda3\\Lib\\site-packages\\ipykernel\\kernelbase.py\", line 429, in dispatch_shell\n",
      "    await result\n",
      "  File \"C:\\Users\\pc\\anaconda3\\Lib\\site-packages\\ipykernel\\kernelbase.py\", line 767, in execute_request\n",
      "    reply_content = await reply_content\n",
      "  File \"C:\\Users\\pc\\anaconda3\\Lib\\site-packages\\ipykernel\\ipkernel.py\", line 429, in do_execute\n",
      "    res = shell.run_cell(\n",
      "  File \"C:\\Users\\pc\\anaconda3\\Lib\\site-packages\\ipykernel\\zmqshell.py\", line 549, in run_cell\n",
      "    return super().run_cell(*args, **kwargs)\n",
      "  File \"C:\\Users\\pc\\anaconda3\\Lib\\site-packages\\IPython\\core\\interactiveshell.py\", line 3075, in run_cell\n",
      "    result = self._run_cell(\n",
      "  File \"C:\\Users\\pc\\anaconda3\\Lib\\site-packages\\IPython\\core\\interactiveshell.py\", line 3130, in _run_cell\n",
      "    result = runner(coro)\n",
      "  File \"C:\\Users\\pc\\anaconda3\\Lib\\site-packages\\IPython\\core\\async_helpers.py\", line 128, in _pseudo_sync_runner\n",
      "    coro.send(None)\n",
      "  File \"C:\\Users\\pc\\anaconda3\\Lib\\site-packages\\IPython\\core\\interactiveshell.py\", line 3334, in run_cell_async\n",
      "    has_raised = await self.run_ast_nodes(code_ast.body, cell_name,\n",
      "  File \"C:\\Users\\pc\\anaconda3\\Lib\\site-packages\\IPython\\core\\interactiveshell.py\", line 3517, in run_ast_nodes\n",
      "    if await self.run_code(code, result, async_=asy):\n",
      "  File \"C:\\Users\\pc\\anaconda3\\Lib\\site-packages\\IPython\\core\\interactiveshell.py\", line 3577, in run_code\n",
      "    exec(code_obj, self.user_global_ns, self.user_ns)\n",
      "  File \"C:\\Users\\pc\\AppData\\Local\\Temp\\ipykernel_7824\\516007724.py\", line 1, in <module>\n",
      "    import gradio as gr\n",
      "  File \"C:\\Users\\pc\\AppData\\Roaming\\Python\\Python312\\site-packages\\gradio\\__init__.py\", line 3, in <module>\n",
      "    import gradio._simple_templates\n",
      "  File \"C:\\Users\\pc\\AppData\\Roaming\\Python\\Python312\\site-packages\\gradio\\_simple_templates\\__init__.py\", line 1, in <module>\n",
      "    from .simpledropdown import SimpleDropdown\n",
      "  File \"C:\\Users\\pc\\AppData\\Roaming\\Python\\Python312\\site-packages\\gradio\\_simple_templates\\simpledropdown.py\", line 6, in <module>\n",
      "    from gradio.components.base import Component, FormComponent\n",
      "  File \"C:\\Users\\pc\\AppData\\Roaming\\Python\\Python312\\site-packages\\gradio\\components\\__init__.py\", line 40, in <module>\n",
      "    from gradio.components.native_plot import BarPlot, LinePlot, NativePlot, ScatterPlot\n",
      "  File \"C:\\Users\\pc\\AppData\\Roaming\\Python\\Python312\\site-packages\\gradio\\components\\native_plot.py\", line 16, in <module>\n",
      "    import pandas as pd\n",
      "  File \"C:\\Users\\pc\\AppData\\Roaming\\Python\\Python312\\site-packages\\pandas\\__init__.py\", line 39, in <module>\n",
      "    from pandas.compat import (\n",
      "  File \"C:\\Users\\pc\\AppData\\Roaming\\Python\\Python312\\site-packages\\pandas\\compat\\__init__.py\", line 27, in <module>\n",
      "    from pandas.compat.pyarrow import (\n",
      "  File \"C:\\Users\\pc\\AppData\\Roaming\\Python\\Python312\\site-packages\\pandas\\compat\\pyarrow.py\", line 8, in <module>\n",
      "    import pyarrow as pa\n",
      "  File \"C:\\Users\\pc\\anaconda3\\Lib\\site-packages\\pyarrow\\__init__.py\", line 65, in <module>\n",
      "    import pyarrow.lib as _lib\n"
     ]
    },
    {
     "ename": "ImportError",
     "evalue": "\nA module that was compiled using NumPy 1.x cannot be run in\nNumPy 2.2.0 as it may crash. To support both 1.x and 2.x\nversions of NumPy, modules must be compiled with NumPy 2.0.\nSome module may need to rebuild instead e.g. with 'pybind11>=2.12'.\n\nIf you are a user of the module, the easiest solution will be to\ndowngrade to 'numpy<2' or try to upgrade the affected module.\nWe expect that some modules will need time to support NumPy 2.\n\n",
     "output_type": "error",
     "traceback": [
      "\u001b[1;31m---------------------------------------------------------------------------\u001b[0m",
      "\u001b[1;31mImportError\u001b[0m                               Traceback (most recent call last)",
      "File \u001b[1;32m~\\AppData\\Roaming\\Python\\Python312\\site-packages\\numpy\\core\\_multiarray_umath.py:44\u001b[0m, in \u001b[0;36m__getattr__\u001b[1;34m(attr_name)\u001b[0m\n\u001b[0;32m     39\u001b[0m     \u001b[38;5;66;03m# Also print the message (with traceback).  This is because old versions\u001b[39;00m\n\u001b[0;32m     40\u001b[0m     \u001b[38;5;66;03m# of NumPy unfortunately set up the import to replace (and hide) the\u001b[39;00m\n\u001b[0;32m     41\u001b[0m     \u001b[38;5;66;03m# error.  The traceback shouldn't be needed, but e.g. pytest plugins\u001b[39;00m\n\u001b[0;32m     42\u001b[0m     \u001b[38;5;66;03m# seem to swallow it and we should be failing anyway...\u001b[39;00m\n\u001b[0;32m     43\u001b[0m     sys\u001b[38;5;241m.\u001b[39mstderr\u001b[38;5;241m.\u001b[39mwrite(msg \u001b[38;5;241m+\u001b[39m tb_msg)\n\u001b[1;32m---> 44\u001b[0m     \u001b[38;5;28;01mraise\u001b[39;00m \u001b[38;5;167;01mImportError\u001b[39;00m(msg)\n\u001b[0;32m     46\u001b[0m ret \u001b[38;5;241m=\u001b[39m \u001b[38;5;28mgetattr\u001b[39m(_multiarray_umath, attr_name, \u001b[38;5;28;01mNone\u001b[39;00m)\n\u001b[0;32m     47\u001b[0m \u001b[38;5;28;01mif\u001b[39;00m ret \u001b[38;5;129;01mis\u001b[39;00m \u001b[38;5;28;01mNone\u001b[39;00m:\n",
      "\u001b[1;31mImportError\u001b[0m: \nA module that was compiled using NumPy 1.x cannot be run in\nNumPy 2.2.0 as it may crash. To support both 1.x and 2.x\nversions of NumPy, modules must be compiled with NumPy 2.0.\nSome module may need to rebuild instead e.g. with 'pybind11>=2.12'.\n\nIf you are a user of the module, the easiest solution will be to\ndowngrade to 'numpy<2' or try to upgrade the affected module.\nWe expect that some modules will need time to support NumPy 2.\n\n"
     ]
    },
    {
     "name": "stderr",
     "output_type": "stream",
     "text": [
      "\n",
      "A module that was compiled using NumPy 1.x cannot be run in\n",
      "NumPy 2.2.0 as it may crash. To support both 1.x and 2.x\n",
      "versions of NumPy, modules must be compiled with NumPy 2.0.\n",
      "Some module may need to rebuild instead e.g. with 'pybind11>=2.12'.\n",
      "\n",
      "If you are a user of the module, the easiest solution will be to\n",
      "downgrade to 'numpy<2' or try to upgrade the affected module.\n",
      "We expect that some modules will need time to support NumPy 2.\n",
      "\n",
      "Traceback (most recent call last):  File \"<frozen runpy>\", line 198, in _run_module_as_main\n",
      "  File \"<frozen runpy>\", line 88, in _run_code\n",
      "  File \"C:\\Users\\pc\\anaconda3\\Lib\\site-packages\\ipykernel_launcher.py\", line 17, in <module>\n",
      "    app.launch_new_instance()\n",
      "  File \"C:\\Users\\pc\\anaconda3\\Lib\\site-packages\\traitlets\\config\\application.py\", line 1075, in launch_instance\n",
      "    app.start()\n",
      "  File \"C:\\Users\\pc\\anaconda3\\Lib\\site-packages\\ipykernel\\kernelapp.py\", line 701, in start\n",
      "    self.io_loop.start()\n",
      "  File \"C:\\Users\\pc\\anaconda3\\Lib\\site-packages\\tornado\\platform\\asyncio.py\", line 205, in start\n",
      "    self.asyncio_loop.run_forever()\n",
      "  File \"C:\\Users\\pc\\anaconda3\\Lib\\asyncio\\windows_events.py\", line 322, in run_forever\n",
      "    super().run_forever()\n",
      "  File \"C:\\Users\\pc\\anaconda3\\Lib\\asyncio\\base_events.py\", line 641, in run_forever\n",
      "    self._run_once()\n",
      "  File \"C:\\Users\\pc\\anaconda3\\Lib\\asyncio\\base_events.py\", line 1986, in _run_once\n",
      "    handle._run()\n",
      "  File \"C:\\Users\\pc\\anaconda3\\Lib\\asyncio\\events.py\", line 88, in _run\n",
      "    self._context.run(self._callback, *self._args)\n",
      "  File \"C:\\Users\\pc\\anaconda3\\Lib\\site-packages\\ipykernel\\kernelbase.py\", line 534, in dispatch_queue\n",
      "    await self.process_one()\n",
      "  File \"C:\\Users\\pc\\anaconda3\\Lib\\site-packages\\ipykernel\\kernelbase.py\", line 523, in process_one\n",
      "    await dispatch(*args)\n",
      "  File \"C:\\Users\\pc\\anaconda3\\Lib\\site-packages\\ipykernel\\kernelbase.py\", line 429, in dispatch_shell\n",
      "    await result\n",
      "  File \"C:\\Users\\pc\\anaconda3\\Lib\\site-packages\\ipykernel\\kernelbase.py\", line 767, in execute_request\n",
      "    reply_content = await reply_content\n",
      "  File \"C:\\Users\\pc\\anaconda3\\Lib\\site-packages\\ipykernel\\ipkernel.py\", line 429, in do_execute\n",
      "    res = shell.run_cell(\n",
      "  File \"C:\\Users\\pc\\anaconda3\\Lib\\site-packages\\ipykernel\\zmqshell.py\", line 549, in run_cell\n",
      "    return super().run_cell(*args, **kwargs)\n",
      "  File \"C:\\Users\\pc\\anaconda3\\Lib\\site-packages\\IPython\\core\\interactiveshell.py\", line 3075, in run_cell\n",
      "    result = self._run_cell(\n",
      "  File \"C:\\Users\\pc\\anaconda3\\Lib\\site-packages\\IPython\\core\\interactiveshell.py\", line 3130, in _run_cell\n",
      "    result = runner(coro)\n",
      "  File \"C:\\Users\\pc\\anaconda3\\Lib\\site-packages\\IPython\\core\\async_helpers.py\", line 128, in _pseudo_sync_runner\n",
      "    coro.send(None)\n",
      "  File \"C:\\Users\\pc\\anaconda3\\Lib\\site-packages\\IPython\\core\\interactiveshell.py\", line 3334, in run_cell_async\n",
      "    has_raised = await self.run_ast_nodes(code_ast.body, cell_name,\n",
      "  File \"C:\\Users\\pc\\anaconda3\\Lib\\site-packages\\IPython\\core\\interactiveshell.py\", line 3517, in run_ast_nodes\n",
      "    if await self.run_code(code, result, async_=asy):\n",
      "  File \"C:\\Users\\pc\\anaconda3\\Lib\\site-packages\\IPython\\core\\interactiveshell.py\", line 3577, in run_code\n",
      "    exec(code_obj, self.user_global_ns, self.user_ns)\n",
      "  File \"C:\\Users\\pc\\AppData\\Local\\Temp\\ipykernel_7824\\516007724.py\", line 1, in <module>\n",
      "    import gradio as gr\n",
      "  File \"C:\\Users\\pc\\AppData\\Roaming\\Python\\Python312\\site-packages\\gradio\\__init__.py\", line 3, in <module>\n",
      "    import gradio._simple_templates\n",
      "  File \"C:\\Users\\pc\\AppData\\Roaming\\Python\\Python312\\site-packages\\gradio\\_simple_templates\\__init__.py\", line 1, in <module>\n",
      "    from .simpledropdown import SimpleDropdown\n",
      "  File \"C:\\Users\\pc\\AppData\\Roaming\\Python\\Python312\\site-packages\\gradio\\_simple_templates\\simpledropdown.py\", line 6, in <module>\n",
      "    from gradio.components.base import Component, FormComponent\n",
      "  File \"C:\\Users\\pc\\AppData\\Roaming\\Python\\Python312\\site-packages\\gradio\\components\\__init__.py\", line 40, in <module>\n",
      "    from gradio.components.native_plot import BarPlot, LinePlot, NativePlot, ScatterPlot\n",
      "  File \"C:\\Users\\pc\\AppData\\Roaming\\Python\\Python312\\site-packages\\gradio\\components\\native_plot.py\", line 16, in <module>\n",
      "    import pandas as pd\n",
      "  File \"C:\\Users\\pc\\AppData\\Roaming\\Python\\Python312\\site-packages\\pandas\\__init__.py\", line 62, in <module>\n",
      "    from pandas.core.api import (\n",
      "  File \"C:\\Users\\pc\\AppData\\Roaming\\Python\\Python312\\site-packages\\pandas\\core\\api.py\", line 9, in <module>\n",
      "    from pandas.core.dtypes.dtypes import (\n",
      "  File \"C:\\Users\\pc\\AppData\\Roaming\\Python\\Python312\\site-packages\\pandas\\core\\dtypes\\dtypes.py\", line 24, in <module>\n",
      "    from pandas._libs import (\n",
      "  File \"C:\\Users\\pc\\anaconda3\\Lib\\site-packages\\pyarrow\\__init__.py\", line 65, in <module>\n",
      "    import pyarrow.lib as _lib\n"
     ]
    },
    {
     "ename": "ImportError",
     "evalue": "\nA module that was compiled using NumPy 1.x cannot be run in\nNumPy 2.2.0 as it may crash. To support both 1.x and 2.x\nversions of NumPy, modules must be compiled with NumPy 2.0.\nSome module may need to rebuild instead e.g. with 'pybind11>=2.12'.\n\nIf you are a user of the module, the easiest solution will be to\ndowngrade to 'numpy<2' or try to upgrade the affected module.\nWe expect that some modules will need time to support NumPy 2.\n\n",
     "output_type": "error",
     "traceback": [
      "\u001b[1;31m---------------------------------------------------------------------------\u001b[0m",
      "\u001b[1;31mImportError\u001b[0m                               Traceback (most recent call last)",
      "File \u001b[1;32m~\\AppData\\Roaming\\Python\\Python312\\site-packages\\numpy\\core\\_multiarray_umath.py:44\u001b[0m, in \u001b[0;36m__getattr__\u001b[1;34m(attr_name)\u001b[0m\n\u001b[0;32m     39\u001b[0m     \u001b[38;5;66;03m# Also print the message (with traceback).  This is because old versions\u001b[39;00m\n\u001b[0;32m     40\u001b[0m     \u001b[38;5;66;03m# of NumPy unfortunately set up the import to replace (and hide) the\u001b[39;00m\n\u001b[0;32m     41\u001b[0m     \u001b[38;5;66;03m# error.  The traceback shouldn't be needed, but e.g. pytest plugins\u001b[39;00m\n\u001b[0;32m     42\u001b[0m     \u001b[38;5;66;03m# seem to swallow it and we should be failing anyway...\u001b[39;00m\n\u001b[0;32m     43\u001b[0m     sys\u001b[38;5;241m.\u001b[39mstderr\u001b[38;5;241m.\u001b[39mwrite(msg \u001b[38;5;241m+\u001b[39m tb_msg)\n\u001b[1;32m---> 44\u001b[0m     \u001b[38;5;28;01mraise\u001b[39;00m \u001b[38;5;167;01mImportError\u001b[39;00m(msg)\n\u001b[0;32m     46\u001b[0m ret \u001b[38;5;241m=\u001b[39m \u001b[38;5;28mgetattr\u001b[39m(_multiarray_umath, attr_name, \u001b[38;5;28;01mNone\u001b[39;00m)\n\u001b[0;32m     47\u001b[0m \u001b[38;5;28;01mif\u001b[39;00m ret \u001b[38;5;129;01mis\u001b[39;00m \u001b[38;5;28;01mNone\u001b[39;00m:\n",
      "\u001b[1;31mImportError\u001b[0m: \nA module that was compiled using NumPy 1.x cannot be run in\nNumPy 2.2.0 as it may crash. To support both 1.x and 2.x\nversions of NumPy, modules must be compiled with NumPy 2.0.\nSome module may need to rebuild instead e.g. with 'pybind11>=2.12'.\n\nIf you are a user of the module, the easiest solution will be to\ndowngrade to 'numpy<2' or try to upgrade the affected module.\nWe expect that some modules will need time to support NumPy 2.\n\n"
     ]
    },
    {
     "name": "stderr",
     "output_type": "stream",
     "text": [
      "\n",
      "A module that was compiled using NumPy 1.x cannot be run in\n",
      "NumPy 2.2.0 as it may crash. To support both 1.x and 2.x\n",
      "versions of NumPy, modules must be compiled with NumPy 2.0.\n",
      "Some module may need to rebuild instead e.g. with 'pybind11>=2.12'.\n",
      "\n",
      "If you are a user of the module, the easiest solution will be to\n",
      "downgrade to 'numpy<2' or try to upgrade the affected module.\n",
      "We expect that some modules will need time to support NumPy 2.\n",
      "\n",
      "Traceback (most recent call last):  File \"<frozen runpy>\", line 198, in _run_module_as_main\n",
      "  File \"<frozen runpy>\", line 88, in _run_code\n",
      "  File \"C:\\Users\\pc\\anaconda3\\Lib\\site-packages\\ipykernel_launcher.py\", line 17, in <module>\n",
      "    app.launch_new_instance()\n",
      "  File \"C:\\Users\\pc\\anaconda3\\Lib\\site-packages\\traitlets\\config\\application.py\", line 1075, in launch_instance\n",
      "    app.start()\n",
      "  File \"C:\\Users\\pc\\anaconda3\\Lib\\site-packages\\ipykernel\\kernelapp.py\", line 701, in start\n",
      "    self.io_loop.start()\n",
      "  File \"C:\\Users\\pc\\anaconda3\\Lib\\site-packages\\tornado\\platform\\asyncio.py\", line 205, in start\n",
      "    self.asyncio_loop.run_forever()\n",
      "  File \"C:\\Users\\pc\\anaconda3\\Lib\\asyncio\\windows_events.py\", line 322, in run_forever\n",
      "    super().run_forever()\n",
      "  File \"C:\\Users\\pc\\anaconda3\\Lib\\asyncio\\base_events.py\", line 641, in run_forever\n",
      "    self._run_once()\n",
      "  File \"C:\\Users\\pc\\anaconda3\\Lib\\asyncio\\base_events.py\", line 1986, in _run_once\n",
      "    handle._run()\n",
      "  File \"C:\\Users\\pc\\anaconda3\\Lib\\asyncio\\events.py\", line 88, in _run\n",
      "    self._context.run(self._callback, *self._args)\n",
      "  File \"C:\\Users\\pc\\anaconda3\\Lib\\site-packages\\ipykernel\\kernelbase.py\", line 534, in dispatch_queue\n",
      "    await self.process_one()\n",
      "  File \"C:\\Users\\pc\\anaconda3\\Lib\\site-packages\\ipykernel\\kernelbase.py\", line 523, in process_one\n",
      "    await dispatch(*args)\n",
      "  File \"C:\\Users\\pc\\anaconda3\\Lib\\site-packages\\ipykernel\\kernelbase.py\", line 429, in dispatch_shell\n",
      "    await result\n",
      "  File \"C:\\Users\\pc\\anaconda3\\Lib\\site-packages\\ipykernel\\kernelbase.py\", line 767, in execute_request\n",
      "    reply_content = await reply_content\n",
      "  File \"C:\\Users\\pc\\anaconda3\\Lib\\site-packages\\ipykernel\\ipkernel.py\", line 429, in do_execute\n",
      "    res = shell.run_cell(\n",
      "  File \"C:\\Users\\pc\\anaconda3\\Lib\\site-packages\\ipykernel\\zmqshell.py\", line 549, in run_cell\n",
      "    return super().run_cell(*args, **kwargs)\n",
      "  File \"C:\\Users\\pc\\anaconda3\\Lib\\site-packages\\IPython\\core\\interactiveshell.py\", line 3075, in run_cell\n",
      "    result = self._run_cell(\n",
      "  File \"C:\\Users\\pc\\anaconda3\\Lib\\site-packages\\IPython\\core\\interactiveshell.py\", line 3130, in _run_cell\n",
      "    result = runner(coro)\n",
      "  File \"C:\\Users\\pc\\anaconda3\\Lib\\site-packages\\IPython\\core\\async_helpers.py\", line 128, in _pseudo_sync_runner\n",
      "    coro.send(None)\n",
      "  File \"C:\\Users\\pc\\anaconda3\\Lib\\site-packages\\IPython\\core\\interactiveshell.py\", line 3334, in run_cell_async\n",
      "    has_raised = await self.run_ast_nodes(code_ast.body, cell_name,\n",
      "  File \"C:\\Users\\pc\\anaconda3\\Lib\\site-packages\\IPython\\core\\interactiveshell.py\", line 3517, in run_ast_nodes\n",
      "    if await self.run_code(code, result, async_=asy):\n",
      "  File \"C:\\Users\\pc\\anaconda3\\Lib\\site-packages\\IPython\\core\\interactiveshell.py\", line 3577, in run_code\n",
      "    exec(code_obj, self.user_global_ns, self.user_ns)\n",
      "  File \"C:\\Users\\pc\\AppData\\Local\\Temp\\ipykernel_7824\\516007724.py\", line 1, in <module>\n",
      "    import gradio as gr\n",
      "  File \"C:\\Users\\pc\\AppData\\Roaming\\Python\\Python312\\site-packages\\gradio\\__init__.py\", line 3, in <module>\n",
      "    import gradio._simple_templates\n",
      "  File \"C:\\Users\\pc\\AppData\\Roaming\\Python\\Python312\\site-packages\\gradio\\_simple_templates\\__init__.py\", line 1, in <module>\n",
      "    from .simpledropdown import SimpleDropdown\n",
      "  File \"C:\\Users\\pc\\AppData\\Roaming\\Python\\Python312\\site-packages\\gradio\\_simple_templates\\simpledropdown.py\", line 6, in <module>\n",
      "    from gradio.components.base import Component, FormComponent\n",
      "  File \"C:\\Users\\pc\\AppData\\Roaming\\Python\\Python312\\site-packages\\gradio\\components\\__init__.py\", line 40, in <module>\n",
      "    from gradio.components.native_plot import BarPlot, LinePlot, NativePlot, ScatterPlot\n",
      "  File \"C:\\Users\\pc\\AppData\\Roaming\\Python\\Python312\\site-packages\\gradio\\components\\native_plot.py\", line 16, in <module>\n",
      "    import pandas as pd\n",
      "  File \"C:\\Users\\pc\\AppData\\Roaming\\Python\\Python312\\site-packages\\pandas\\__init__.py\", line 62, in <module>\n",
      "    from pandas.core.api import (\n",
      "  File \"C:\\Users\\pc\\AppData\\Roaming\\Python\\Python312\\site-packages\\pandas\\core\\api.py\", line 28, in <module>\n",
      "    from pandas.core.arrays import Categorical\n",
      "  File \"C:\\Users\\pc\\AppData\\Roaming\\Python\\Python312\\site-packages\\pandas\\core\\arrays\\__init__.py\", line 1, in <module>\n",
      "    from pandas.core.arrays.arrow import ArrowExtensionArray\n",
      "  File \"C:\\Users\\pc\\AppData\\Roaming\\Python\\Python312\\site-packages\\pandas\\core\\arrays\\arrow\\__init__.py\", line 5, in <module>\n",
      "    from pandas.core.arrays.arrow.array import ArrowExtensionArray\n",
      "  File \"C:\\Users\\pc\\AppData\\Roaming\\Python\\Python312\\site-packages\\pandas\\core\\arrays\\arrow\\array.py\", line 50, in <module>\n",
      "    from pandas.core import (\n",
      "  File \"C:\\Users\\pc\\AppData\\Roaming\\Python\\Python312\\site-packages\\pandas\\core\\ops\\__init__.py\", line 8, in <module>\n",
      "    from pandas.core.ops.array_ops import (\n",
      "  File \"C:\\Users\\pc\\AppData\\Roaming\\Python\\Python312\\site-packages\\pandas\\core\\ops\\array_ops.py\", line 56, in <module>\n",
      "    from pandas.core.computation import expressions\n",
      "  File \"C:\\Users\\pc\\AppData\\Roaming\\Python\\Python312\\site-packages\\pandas\\core\\computation\\expressions.py\", line 21, in <module>\n",
      "    from pandas.core.computation.check import NUMEXPR_INSTALLED\n",
      "  File \"C:\\Users\\pc\\AppData\\Roaming\\Python\\Python312\\site-packages\\pandas\\core\\computation\\check.py\", line 5, in <module>\n",
      "    ne = import_optional_dependency(\"numexpr\", errors=\"warn\")\n",
      "  File \"C:\\Users\\pc\\AppData\\Roaming\\Python\\Python312\\site-packages\\pandas\\compat\\_optional.py\", line 135, in import_optional_dependency\n",
      "    module = importlib.import_module(name)\n",
      "  File \"C:\\Users\\pc\\anaconda3\\Lib\\importlib\\__init__.py\", line 90, in import_module\n",
      "    return _bootstrap._gcd_import(name[level:], package, level)\n",
      "  File \"C:\\Users\\pc\\anaconda3\\Lib\\site-packages\\numexpr\\__init__.py\", line 24, in <module>\n",
      "    from numexpr.interpreter import MAX_THREADS, use_vml, __BLOCK_SIZE1__\n"
     ]
    },
    {
     "ename": "AttributeError",
     "evalue": "_ARRAY_API not found",
     "output_type": "error",
     "traceback": [
      "\u001b[1;31m---------------------------------------------------------------------------\u001b[0m",
      "\u001b[1;31mAttributeError\u001b[0m                            Traceback (most recent call last)",
      "\u001b[1;31mAttributeError\u001b[0m: _ARRAY_API not found"
     ]
    },
    {
     "name": "stderr",
     "output_type": "stream",
     "text": [
      "\n",
      "A module that was compiled using NumPy 1.x cannot be run in\n",
      "NumPy 2.2.0 as it may crash. To support both 1.x and 2.x\n",
      "versions of NumPy, modules must be compiled with NumPy 2.0.\n",
      "Some module may need to rebuild instead e.g. with 'pybind11>=2.12'.\n",
      "\n",
      "If you are a user of the module, the easiest solution will be to\n",
      "downgrade to 'numpy<2' or try to upgrade the affected module.\n",
      "We expect that some modules will need time to support NumPy 2.\n",
      "\n",
      "Traceback (most recent call last):  File \"<frozen runpy>\", line 198, in _run_module_as_main\n",
      "  File \"<frozen runpy>\", line 88, in _run_code\n",
      "  File \"C:\\Users\\pc\\anaconda3\\Lib\\site-packages\\ipykernel_launcher.py\", line 17, in <module>\n",
      "    app.launch_new_instance()\n",
      "  File \"C:\\Users\\pc\\anaconda3\\Lib\\site-packages\\traitlets\\config\\application.py\", line 1075, in launch_instance\n",
      "    app.start()\n",
      "  File \"C:\\Users\\pc\\anaconda3\\Lib\\site-packages\\ipykernel\\kernelapp.py\", line 701, in start\n",
      "    self.io_loop.start()\n",
      "  File \"C:\\Users\\pc\\anaconda3\\Lib\\site-packages\\tornado\\platform\\asyncio.py\", line 205, in start\n",
      "    self.asyncio_loop.run_forever()\n",
      "  File \"C:\\Users\\pc\\anaconda3\\Lib\\asyncio\\windows_events.py\", line 322, in run_forever\n",
      "    super().run_forever()\n",
      "  File \"C:\\Users\\pc\\anaconda3\\Lib\\asyncio\\base_events.py\", line 641, in run_forever\n",
      "    self._run_once()\n",
      "  File \"C:\\Users\\pc\\anaconda3\\Lib\\asyncio\\base_events.py\", line 1986, in _run_once\n",
      "    handle._run()\n",
      "  File \"C:\\Users\\pc\\anaconda3\\Lib\\asyncio\\events.py\", line 88, in _run\n",
      "    self._context.run(self._callback, *self._args)\n",
      "  File \"C:\\Users\\pc\\anaconda3\\Lib\\site-packages\\ipykernel\\kernelbase.py\", line 534, in dispatch_queue\n",
      "    await self.process_one()\n",
      "  File \"C:\\Users\\pc\\anaconda3\\Lib\\site-packages\\ipykernel\\kernelbase.py\", line 523, in process_one\n",
      "    await dispatch(*args)\n",
      "  File \"C:\\Users\\pc\\anaconda3\\Lib\\site-packages\\ipykernel\\kernelbase.py\", line 429, in dispatch_shell\n",
      "    await result\n",
      "  File \"C:\\Users\\pc\\anaconda3\\Lib\\site-packages\\ipykernel\\kernelbase.py\", line 767, in execute_request\n",
      "    reply_content = await reply_content\n",
      "  File \"C:\\Users\\pc\\anaconda3\\Lib\\site-packages\\ipykernel\\ipkernel.py\", line 429, in do_execute\n",
      "    res = shell.run_cell(\n",
      "  File \"C:\\Users\\pc\\anaconda3\\Lib\\site-packages\\ipykernel\\zmqshell.py\", line 549, in run_cell\n",
      "    return super().run_cell(*args, **kwargs)\n",
      "  File \"C:\\Users\\pc\\anaconda3\\Lib\\site-packages\\IPython\\core\\interactiveshell.py\", line 3075, in run_cell\n",
      "    result = self._run_cell(\n",
      "  File \"C:\\Users\\pc\\anaconda3\\Lib\\site-packages\\IPython\\core\\interactiveshell.py\", line 3130, in _run_cell\n",
      "    result = runner(coro)\n",
      "  File \"C:\\Users\\pc\\anaconda3\\Lib\\site-packages\\IPython\\core\\async_helpers.py\", line 128, in _pseudo_sync_runner\n",
      "    coro.send(None)\n",
      "  File \"C:\\Users\\pc\\anaconda3\\Lib\\site-packages\\IPython\\core\\interactiveshell.py\", line 3334, in run_cell_async\n",
      "    has_raised = await self.run_ast_nodes(code_ast.body, cell_name,\n",
      "  File \"C:\\Users\\pc\\anaconda3\\Lib\\site-packages\\IPython\\core\\interactiveshell.py\", line 3517, in run_ast_nodes\n",
      "    if await self.run_code(code, result, async_=asy):\n",
      "  File \"C:\\Users\\pc\\anaconda3\\Lib\\site-packages\\IPython\\core\\interactiveshell.py\", line 3577, in run_code\n",
      "    exec(code_obj, self.user_global_ns, self.user_ns)\n",
      "  File \"C:\\Users\\pc\\AppData\\Local\\Temp\\ipykernel_7824\\516007724.py\", line 1, in <module>\n",
      "    import gradio as gr\n",
      "  File \"C:\\Users\\pc\\AppData\\Roaming\\Python\\Python312\\site-packages\\gradio\\__init__.py\", line 3, in <module>\n",
      "    import gradio._simple_templates\n",
      "  File \"C:\\Users\\pc\\AppData\\Roaming\\Python\\Python312\\site-packages\\gradio\\_simple_templates\\__init__.py\", line 1, in <module>\n",
      "    from .simpledropdown import SimpleDropdown\n",
      "  File \"C:\\Users\\pc\\AppData\\Roaming\\Python\\Python312\\site-packages\\gradio\\_simple_templates\\simpledropdown.py\", line 6, in <module>\n",
      "    from gradio.components.base import Component, FormComponent\n",
      "  File \"C:\\Users\\pc\\AppData\\Roaming\\Python\\Python312\\site-packages\\gradio\\components\\__init__.py\", line 40, in <module>\n",
      "    from gradio.components.native_plot import BarPlot, LinePlot, NativePlot, ScatterPlot\n",
      "  File \"C:\\Users\\pc\\AppData\\Roaming\\Python\\Python312\\site-packages\\gradio\\components\\native_plot.py\", line 16, in <module>\n",
      "    import pandas as pd\n",
      "  File \"C:\\Users\\pc\\AppData\\Roaming\\Python\\Python312\\site-packages\\pandas\\__init__.py\", line 62, in <module>\n",
      "    from pandas.core.api import (\n",
      "  File \"C:\\Users\\pc\\AppData\\Roaming\\Python\\Python312\\site-packages\\pandas\\core\\api.py\", line 28, in <module>\n",
      "    from pandas.core.arrays import Categorical\n",
      "  File \"C:\\Users\\pc\\AppData\\Roaming\\Python\\Python312\\site-packages\\pandas\\core\\arrays\\__init__.py\", line 1, in <module>\n",
      "    from pandas.core.arrays.arrow import ArrowExtensionArray\n",
      "  File \"C:\\Users\\pc\\AppData\\Roaming\\Python\\Python312\\site-packages\\pandas\\core\\arrays\\arrow\\__init__.py\", line 5, in <module>\n",
      "    from pandas.core.arrays.arrow.array import ArrowExtensionArray\n",
      "  File \"C:\\Users\\pc\\AppData\\Roaming\\Python\\Python312\\site-packages\\pandas\\core\\arrays\\arrow\\array.py\", line 64, in <module>\n",
      "    from pandas.core.arrays.masked import BaseMaskedArray\n",
      "  File \"C:\\Users\\pc\\AppData\\Roaming\\Python\\Python312\\site-packages\\pandas\\core\\arrays\\masked.py\", line 60, in <module>\n",
      "    from pandas.core import (\n",
      "  File \"C:\\Users\\pc\\AppData\\Roaming\\Python\\Python312\\site-packages\\pandas\\core\\nanops.py\", line 52, in <module>\n",
      "    bn = import_optional_dependency(\"bottleneck\", errors=\"warn\")\n",
      "  File \"C:\\Users\\pc\\AppData\\Roaming\\Python\\Python312\\site-packages\\pandas\\compat\\_optional.py\", line 135, in import_optional_dependency\n",
      "    module = importlib.import_module(name)\n",
      "  File \"C:\\Users\\pc\\anaconda3\\Lib\\importlib\\__init__.py\", line 90, in import_module\n",
      "    return _bootstrap._gcd_import(name[level:], package, level)\n",
      "  File \"C:\\Users\\pc\\anaconda3\\Lib\\site-packages\\bottleneck\\__init__.py\", line 7, in <module>\n",
      "    from .move import (move_argmax, move_argmin, move_max, move_mean, move_median,\n"
     ]
    },
    {
     "ename": "ImportError",
     "evalue": "\nA module that was compiled using NumPy 1.x cannot be run in\nNumPy 2.2.0 as it may crash. To support both 1.x and 2.x\nversions of NumPy, modules must be compiled with NumPy 2.0.\nSome module may need to rebuild instead e.g. with 'pybind11>=2.12'.\n\nIf you are a user of the module, the easiest solution will be to\ndowngrade to 'numpy<2' or try to upgrade the affected module.\nWe expect that some modules will need time to support NumPy 2.\n\n",
     "output_type": "error",
     "traceback": [
      "\u001b[1;31m---------------------------------------------------------------------------\u001b[0m",
      "\u001b[1;31mImportError\u001b[0m                               Traceback (most recent call last)",
      "File \u001b[1;32m~\\AppData\\Roaming\\Python\\Python312\\site-packages\\numpy\\core\\_multiarray_umath.py:44\u001b[0m, in \u001b[0;36m__getattr__\u001b[1;34m(attr_name)\u001b[0m\n\u001b[0;32m     39\u001b[0m     \u001b[38;5;66;03m# Also print the message (with traceback).  This is because old versions\u001b[39;00m\n\u001b[0;32m     40\u001b[0m     \u001b[38;5;66;03m# of NumPy unfortunately set up the import to replace (and hide) the\u001b[39;00m\n\u001b[0;32m     41\u001b[0m     \u001b[38;5;66;03m# error.  The traceback shouldn't be needed, but e.g. pytest plugins\u001b[39;00m\n\u001b[0;32m     42\u001b[0m     \u001b[38;5;66;03m# seem to swallow it and we should be failing anyway...\u001b[39;00m\n\u001b[0;32m     43\u001b[0m     sys\u001b[38;5;241m.\u001b[39mstderr\u001b[38;5;241m.\u001b[39mwrite(msg \u001b[38;5;241m+\u001b[39m tb_msg)\n\u001b[1;32m---> 44\u001b[0m     \u001b[38;5;28;01mraise\u001b[39;00m \u001b[38;5;167;01mImportError\u001b[39;00m(msg)\n\u001b[0;32m     46\u001b[0m ret \u001b[38;5;241m=\u001b[39m \u001b[38;5;28mgetattr\u001b[39m(_multiarray_umath, attr_name, \u001b[38;5;28;01mNone\u001b[39;00m)\n\u001b[0;32m     47\u001b[0m \u001b[38;5;28;01mif\u001b[39;00m ret \u001b[38;5;129;01mis\u001b[39;00m \u001b[38;5;28;01mNone\u001b[39;00m:\n",
      "\u001b[1;31mImportError\u001b[0m: \nA module that was compiled using NumPy 1.x cannot be run in\nNumPy 2.2.0 as it may crash. To support both 1.x and 2.x\nversions of NumPy, modules must be compiled with NumPy 2.0.\nSome module may need to rebuild instead e.g. with 'pybind11>=2.12'.\n\nIf you are a user of the module, the easiest solution will be to\ndowngrade to 'numpy<2' or try to upgrade the affected module.\nWe expect that some modules will need time to support NumPy 2.\n\n"
     ]
    },
    {
     "name": "stdout",
     "output_type": "stream",
     "text": [
      "Loading data...\n",
      "Loading data from: C:\\Users\\pc\\Downloads\\dataset folder\\Border_Crossing_Entry_Data.csv\n",
      "Loaded data shape: (1000, 12)\n",
      "\n",
      "First few rows of coordinates:\n",
      "   Latitude  Longitude\n",
      "0    48.608    -93.401\n",
      "1    49.002   -122.265\n",
      "2    31.334   -109.948\n",
      "3    48.999   -110.215\n",
      "4    45.189    -67.275\n",
      "\n",
      "Creating Gradio interface...\n",
      "\n",
      "Launching application...\n",
      "Running on local URL:  http://127.0.0.1:7860\n",
      "Running on public URL: https://f20bc99f4470b9a473.gradio.live\n",
      "\n",
      "This share link expires in 72 hours. For free permanent hosting and GPU upgrades, run `gradio deploy` from Terminal to deploy to Spaces (https://huggingface.co/spaces)\n"
     ]
    },
    {
     "data": {
      "text/html": [
       "<div><iframe src=\"https://f20bc99f4470b9a473.gradio.live\" width=\"100%\" height=\"500\" allow=\"autoplay; camera; microphone; clipboard-read; clipboard-write;\" frameborder=\"0\" allowfullscreen></iframe></div>"
      ],
      "text/plain": [
       "<IPython.core.display.HTML object>"
      ]
     },
     "metadata": {},
     "output_type": "display_data"
    }
   ],
   "source": [
    "import gradio as gr  \n",
    "from gradio_folium import Folium  \n",
    "import folium  \n",
    "import pandas as pd  \n",
    "from pathlib import Path  \n",
    "\n",
    "def load_data():  \n",
    "    # Load and prepare the data  \n",
    "    file_path = Path(r\"C:\\Users\\pc\\Downloads\\dataset folder\\Border_Crossing_Entry_Data.csv\")  \n",
    "    print(f\"Loading data from: {file_path}\")  \n",
    "    df = pd.read_csv(file_path)  \n",
    "\n",
    "    # Clean the coordinate data  \n",
    "    df['Latitude'] = pd.to_numeric(df['Latitude'], errors='coerce')  \n",
    "    df['Longitude'] = pd.to_numeric(df['Longitude'], errors='coerce')  \n",
    "    df = df.dropna(subset=['Latitude', 'Longitude'])  \n",
    "\n",
    "    print(f\"Loaded data shape: {df.shape}\")  \n",
    "    print(\"\\nFirst few rows of coordinates:\")  \n",
    "    print(df[['Latitude', 'Longitude']].head())  \n",
    "\n",
    "    return df  \n",
    "\n",
    "def select(evt: gr.SelectData):  \n",
    "    row = df.iloc[evt.index[0]]  \n",
    "    m = folium.Map(location=[row['Latitude'], row['Longitude']], zoom_start=10)  \n",
    "    folium.Marker(  \n",
    "        [row['Latitude'], row['Longitude']],  \n",
    "        popup=f\"Location: {row['Port Name']}\" if 'Port Name' in row else \"Selected Location\"  \n",
    "    ).add_to(m)  \n",
    "    return m  \n",
    "\n",
    "try:  \n",
    "    print(\"Loading data...\")  \n",
    "    df = load_data()  \n",
    "\n",
    "    print(\"\\nCreating Gradio interface...\")  \n",
    "    with gr.Blocks() as demo:  \n",
    "        gr.Markdown(\"# Border Crossing Entry Data Visualization\")  \n",
    "\n",
    "        initial_location = [df['Latitude'].iloc[0], df['Longitude'].iloc[0]]  \n",
    "        initial_map = folium.Map(location=initial_location, zoom_start=4)  \n",
    "        folium.Marker(initial_location, popup=\"Initial Location\").add_to(initial_map)  \n",
    "\n",
    "        with gr.Row():  \n",
    "            dataframe = gr.Dataframe(  \n",
    "                value=df,  \n",
    "                headers=list(df.columns),  \n",
    "                row_count=(10, \"dynamic\"),  \n",
    "                interactive=False,  \n",
    "                wrap=True  \n",
    "            )  \n",
    "\n",
    "            map_component = Folium(value=initial_map, height=500)  \n",
    "\n",
    "        dataframe.select(fn=select, outputs=map_component)  \n",
    "\n",
    "    print(\"\\nLaunching application...\")  \n",
    "    demo.launch(share=True)  \n",
    "\n",
    "except Exception as e:  \n",
    "    print(f\"\\nError occurred: {str(e)}\")  "
   ]
  },
  {
   "cell_type": "code",
   "execution_count": null,
   "id": "178ced9e-348c-474f-8eb7-e8ffd003ed6d",
   "metadata": {},
   "outputs": [],
   "source": []
  }
 ],
 "metadata": {
  "kernelspec": {
   "display_name": "Python 3 (ipykernel)",
   "language": "python",
   "name": "python3"
  },
  "language_info": {
   "codemirror_mode": {
    "name": "ipython",
    "version": 3
   },
   "file_extension": ".py",
   "mimetype": "text/x-python",
   "name": "python",
   "nbconvert_exporter": "python",
   "pygments_lexer": "ipython3",
   "version": "3.12.7"
  }
 },
 "nbformat": 4,
 "nbformat_minor": 5
}
